### 异常与错误的区别

错误（Error）：错误可以避免，错误分为：

+ 逻辑错误：算法写错了（最难找）

+ 语法错误：变量名写错了,无法编成字节码，一句都不会执行(SytaxError)

  

异常（Exception）：异常是可以避免的，由某些不确定因素引起的

比如打开一个文件，发现文件不存在，这是异常



### 常使用的异常结构

常用的异常处理结构：else一般不会被用到其他语句基本上都会被用到

```python
# try和finall后面一般可以再加try,except, except后面一般不加
# else后面只要有异常都不会执行，这个异常是指最外部的except，没有捕获到，
# 如下面的例子，异常被里面的try except捕获到了，所以外面的else还是会执行
# finally #有异常，或者没有异常， 或者异常有没有被捕获到都会执行
def foo():
    try:
        try:
            print('999999')
            f = open('2wwe2233', encoding='utf8')
            print('@@@@@')
        except FileNotFoundError as e:
            print(e)

    except ArithmeticError as e:
        print('error')
    else:
        print('no error')
    finally:
        print('fin')
        try:
            f.close()
        except:
            pass
#foo()

```

### 异常在多线程中的应用

raise会将当前子线程的异常，抛出到主线程

```python
import time
import threading

def foo():
    try:
        print('999999')
        f = open('2wwe2233', encoding='utf8')
        print('@@@@@')
    except Exception as e:
        print(e)
        raise #子线程异常会向外抛出，但是主线程还是会执行完成
    finally:
        print('fin')
        try:
            f.close()
        except:
            pass

def bar():
    print('before')
    time.sleep(3)
    x = foo() #子线程遇到异常中断，返回None
    print(x)
    print('after')
# 解释器执行时，每一个进程至少有一个线程，即主线程__main__
t = threading.Thread(target=bar) #bar是主线程，foo()是子线程，当子线程中断时，主线程接着执行，直到满足次数退出，
# 表示程序正常退出，虽然子线程中断，但是主线程正常退出，exit code 0，
t.start()

count = 1
while True:
    time.sleep(1)
    print(threading.enumerate()) #打印当前正在运行的线程
    count += 1
    if count > 5:
        break
```



raise会将当前子线程的异常，抛出到主线程，但是主线程使用了一个try 语句

所以使用两个raise

```python
# 使用2个raise的例子
def foo():
    try:
        print('999999')
        f = open('2wwe2233', encoding='utf8')
        print('@@@@@')
    except Exception as e:
        print(e)
        raise #reraise 抛出最近激活的异常
    finally:
        print('fin')
        try:
            f.close()
        except:
            pass

def bar():
    print('before')
    time.sleep(3)
    try:
        foo() #子线程遇到异常中断，返回None
    except Exception as e:
        print(type(e), e)
        raise
    print('after')

t = threading.Thread(target=bar)
t.start()

count = 1
while True:
    time.sleep(1)
    print(threading.enumerate())
    count += 1
    if count > 5:
        break
```

### raise语句的三种用法

raise后面加自定义类名字，raise后面加内建异常名字，raise后面什么都不加直接将异常抛出，多线程用的比较多。

raise后面加自定义类名字例子：

```python
#例1,自定义异常
class MyError(Exception):
    pass


def foo():
    try:
        print('*' * 10)
        raise MyError #这个名字只能是BaseException 的子类,  默认调用无参构造器
        print('*' * 10)
    except BaseException:
        print('error')
    print('#######')
foo()  #  打印一次星星， 打印error，打印####


#例2,自定义带参数异常
class MyError(Exception):
    def __init__(self, a, b):
        self.a = a
        self.b = b


def foo():
    try:
        print('*' * 10)
        raise MyError(1, 2)
        #raise MyError # 给不给参数1，2都会Exception,BaseException等异常捕获，因为只主动抛出异常
        print('*' * 10)
    except MyError as e:
        print('myerrpr')
    except RuntimeError as e:
        print('runtimeerror')
    except ArithmeticError as e:
        print('arithmeticerror')
    except ZeroDivisionError as e:
        print('zerodivisionerror')
    except Exception as e:
        print('exception')
    except BaseException as e:
        print('baseexception')
    except:
        pass
    print('$$$$$')
foo()  #  打印一次星星， 打印myerrpr，打印$$$$$
```

### 异常的其他例子

```python
#例1
def foo():
    try:
        print('*' * 10)
        raise Exception
        print('*' * 10)
    except ZeroDivisionError:
        print('zero errpr')
    print('#######')
foo() # 只会打印一次星星，并且输出到stderror

#例2
import sys
def foo():
    try:
        print('*' * 10)
        sys.exit(0)  #SystemExit异常 -1 2 1.d都是同样的结果
        print('*' * 10)
    except:
        print('error')
    print('#######')
#foo() # 打印一次星星，打印error，打印####


#例3
def foo():
    try:
        print('*' * 10)
        input()
        print('*' * 10)
    except KeyboardInterrupt:  # 只用按住crtl + c 才会捕获异常
        print('error')
    print('#######')
foo() # 打印一次星星，打印error，打印####


#例4
def foo():
    try:
        print('*' * 10)
        raise {}
        print('*' * 10)
    except Exception as e:
        print('all except', e) # all except exceptions must derive from BaseException
    print('+++++')
foo()

#例5
def foo():
    try:
        print('999999')
        f = open('2wwe2233', encoding='utf8')
        print('@@@@@')
    except:
        print('error')
    finally:
        print('fin')
        try:
            f.close()
        except:
            pass
#运行代码会打印 error fin
```

### 在异常语句中使用return（以下代码只用来测试）

+ 当return语句遇到finally语句，不会立即返回，会先执行finally再return，见例1

  例2

+ 函数执行过程中，如果遇到异常，函数最后的return不会返回，默认返回None，见例3，例5

+ 在finally或except中加return或break会压制异常，见例4

+ 在一个函数中使用2个return，见例4，最后返回的是finally中的return

```python
#以下代码只用来测试
#1
def foo():
    try:
        return 3
    finally:
        print('fin')
print(foo()) # 先打印再返回3

#2
def foo():
    try:
        print('++++')
        return 3
        print('----')
    finally:
        print('fin')
print(foo()) # 先打印+++,  再打印fin, 最后返回3

#3
def foo():
    try:
        print('++++')
        1/0
        return 3  #或者写在函数的最末尾
        print('----')
    except:
        print('@@@@@@')
    finally:
        print('fin')
print(foo()) # 先打印+++,  然后@@@@@，再打印fin，返回None，return3不执行

# 4
#在except或者finally中使用return 或者break会压制异常
def foo():
    try:
        print('++++')
        1/0
        return 3
        print('----')
    except:
        print('@@@@@@')
    finally:
        print('fin')
        return 5
print(foo()) # 先打印+++,  然后@@@@@，再打印fin，return5

#5

def foo():
    try:
        print('++++')
        1/0
        print('----')
    except RuntimeError:
        print('@@@@@@')
    finally:
        print('fin')
    return 3
print(foo()) # 先打印+++,再打印fin，异常向外抛出，中断进程，不执行return3
```